data/output/KING.txt
PASSIVE SELL 1660.00 @ 1322.22
PASSIVE SELL 460.00 @ 1322.33
PASSIVE BUY 1540.00 @ 1321.75
PASSIVE BUY 2260.00 @ 1321.71
PASSIVE SELL 1740.00 @ 1322.20
PASSIVE SELL 660.00 @ 1322.19
PASSIVE BUY 2260.00 @ 1321.76
PASSIVE SELL 1940.00 @ 1322.16
PASSIVE BUY 1740.00 @ 1321.75
PASSIVE SELL 1700.00 @ 1322.18
PASSIVE SELL 860.00 @ 1322.03
CANCEL SELL 460.00 @ 1322.33
PASSIVE BUY 1380.00 @ 1321.91
PASSIVE BUY 2540.00 @ 1321.89
PASSIVE SELL 1700.00 @ 1321.98
CANCEL SELL 1660.00 @ 1322.22
AGGRESSIVE SELL 1180.00 @ 1321.91
PASSIVE SELL 460.00 @ 1321.96
CANCEL SELL 1740.00 @ 1322.20
AGGRESSIVE BUY 1500.00 @ 1321.98
PASSIVE BUY 1580.00 @ 1321.93
PASSIVE SELL 620.00 @ 1321.99
PASSIVE SELL 1740.00 @ 1322.00
CANCEL SELL 660.00 @ 1322.19
AGGRESSIVE SELL 1940.00 @ 1321.89
PASSIVE SELL 1820.00 @ 1321.94
CANCEL SELL 1700.00 @ 1322.18
AGGRESSIVE BUY 2820.00 @ 1321.99
PASSIVE BUY 1220.00 @ 1321.92
AGGRESSIVE BUY 740.00 @ 1322.00
PASSIVE SELL 1100.00 @ 1322.02
PASSIVE BUY 2220.00 @ 1321.81
PASSIVE SELL 940.00 @ 1322.02
PASSIVE BUY 940.00 @ 1321.89
AGGRESSIVE SELL 1580.00 @ 1321.89
PASSIVE BUY 2460.00 @ 1321.89
AGGRESSIVE SELL 860.00 @ 1321.89
PASSIVE SELL 500.00 @ 1322.11
PASSIVE BUY 1140.00 @ 1321.78
PASSIVE BUY 1460.00 @ 1321.90
CANCEL BUY -1540.00 @ 1321.75
CANCEL BUY 2260.00 @ 1321.71
CANCEL BUY 2260.00 @ 1321.76
CANCEL BUY 1740.00 @ 1321.75
CANCEL BUY -1160.00 @ 1321.89
CANCEL BUY 2220.00 @ 1321.81
CANCEL BUY -940.00 @ 1321.89
CANCEL BUY 2460.00 @ 1321.89
CANCEL BUY 1140.00 @ 1321.78
CANCEL BUY 1460.00 @ 1321.90
PASSIVE SELL 1420.00 @ 1321.97
PASSIVE SELL 1740.00 @ 1321.88
CANCEL SELL 1940.00 @ 1322.16
AGGRESSIVE BUY 1820.00 @ 1321.97
PASSIVE BUY 1380.00 @ 1321.94
AGGRESSIVE SELL 1420.00 @ 1321.93
PASSIVE SELL 1940.00 @ 1321.76
CANCEL SELL 500.00 @ 1322.11
AGGRESSIVE BUY 1900.00 @ 1321.76
AGGRESSIVE BUY 1860.00 @ 1321.86
PASSIVE BUY 2500.00 @ 1321.85
AGGRESSIVE SELL 1620.00 @ 1321.86
AGGRESSIVE BUY 900.00 @ 1321.93
AGGRESSIVE BUY 2220.00 @ 1322.00
PASSIVE BUY 1820.00 @ 1321.99
AGGRESSIVE BUY 1340.00 @ 1322.02
AGGRESSIVE SELL 980.00 @ 1321.99
PASSIVE SELL 2260.00 @ 1322.00
AGGRESSIVE BUY 1180.00 @ 1322.00
PASSIVE BUY 2700.00 @ 1321.99
PASSIVE BUY 1700.00 @ 1321.84
AGGRESSIVE BUY 2020.00 @ 1322.02
AGGRESSIVE SELL 980.00 @ 1321.99
AGGRESSIVE SELL 940.00 @ 1321.99
PASSIVE SELL 2260.00 @ 1322.03
AGGRESSIVE BUY 2500.00 @ 1322.03
AGGRESSIVE SELL 1460.00 @ 1321.99
PASSIVE BUY 1900.00 @ 1321.99
AGGRESSIVE SELL 2180.00 @ 1321.93
AGGRESSIVE BUY 1780.00 @ 1322.03
PASSIVE SELL 380.00 @ 1322.13
PASSIVE BUY 2060.00 @ 1322.12
PASSIVE SELL 420.00 @ 1322.18
AGGRESSIVE BUY 1860.00 @ 1322.24
CANCEL BUY 200.00 @ 1321.86
CANCEL BUY 2500.00 @ 1321.85
CANCEL BUY 740.00 @ 1321.93
CANCEL BUY 1700.00 @ 1321.84
CANCEL BUY 1000.00 @ 1322.03
CANCEL BUY 2060.00 @ 1322.12
CANCEL BUY 1060.00 @ 1322.24
PASSIVE BUY 2020.00 @ 1321.87
PASSIVE SELL 1380.00 @ 1322.45
PASSIVE SELL 2260.00 @ 1322.48
PASSIVE SELL 900.00 @ 1322.43
PASSIVE BUY 2900.00 @ 1321.93
PASSIVE BUY 2220.00 @ 1322.04
PASSIVE SELL 1060.00 @ 1322.28
PASSIVE SELL 740.00 @ 1322.25
PASSIVE SELL 1500.00 @ 1322.16
AGGRESSIVE SELL 2300.00 @ 1321.99
CANCEL SELL 2260.00 @ 1322.48
PASSIVE SELL 1420.00 @ 1321.97
CANCEL SELL 1380.00 @ 1322.45
AGGRESSIVE SELL 1660.00 @ 1321.93
PASSIVE SELL 860.00 @ 1322.06
CANCEL SELL 900.00 @ 1322.43
AGGRESSIVE SELL 2300.00 @ 1321.90
CANCEL SELL 1060.00 @ 1322.28
PASSIVE SELL 1820.00 @ 1321.96
CANCEL SELL 740.00 @ 1322.25
AGGRESSIVE SELL 580.00 @ 1321.87
PASSIVE BUY 1300.00 @ 1321.87
PASSIVE SELL 1780.00 @ 1321.89
CANCEL SELL 1500.00 @ 1322.16
AGGRESSIVE SELL 1260.00 @ 1321.87
AGGRESSIVE SELL 1860.00 @ 1321.73
CANCEL SELL 860.00 @ 1322.06
PASSIVE SELL 1500.00 @ 1321.65
CANCEL SELL 80.00 @ 1321.99
AGGRESSIVE BUY 2260.00 @ 1321.75
PASSIVE BUY 1940.00 @ 1321.67
PASSIVE BUY 2340.00 @ 1321.88
AGGRESSIVE BUY 1660.00 @ 1321.89
AGGRESSIVE BUY 980.00 @ 1321.90
PASSIVE BUY 2140.00 @ 1321.86
PASSIVE BUY 1500.00 @ 1321.73
AGGRESSIVE SELL 1540.00 @ 1321.88
AGGRESSIVE SELL 2020.00 @ 1321.86
PASSIVE BUY 1260.00 @ 1321.82
AGGRESSIVE BUY 1060.00 @ 1321.96
PASSIVE BUY 2300.00 @ 1321.87
AGGRESSIVE BUY 1380.00 @ 1321.97
PASSIVE BUY 1900.00 @ 1321.96
CANCEL BUY 380.00 @ 1321.75
CANCEL BUY 1940.00 @ 1321.67
CANCEL BUY 920.00 @ 1321.86
CANCEL BUY 1500.00 @ 1321.73
CANCEL BUY 1260.00 @ 1321.82
CANCEL BUY 2300.00 @ 1321.87
CANCEL BUY 1900.00 @ 1321.96
PASSIVE SELL 580.00 @ 1322.07
PASSIVE BUY 2300.00 @ 1321.85
PASSIVE SELL 1900.00 @ 1321.88
PASSIVE SELL 2020.00 @ 1321.99
AGGRESSIVE SELL 2060.00 @ 1321.85
PASSIVE BUY 940.00 @ 1321.81
AGGRESSIVE SELL 1620.00 @ 1321.84
PASSIVE SELL 2100.00 @ 1321.83
PASSIVE SELL 1820.00 @ 1321.82
CANCEL SELL 580.00 @ 1322.07
AGGRESSIVE BUY 2620.00 @ 1321.83
PASSIVE SELL 1220.00 @ 1321.86
PASSIVE SELL 1420.00 @ 1321.82
CANCEL SELL 2020.00 @ 1321.99
AGGRESSIVE SELL 2020.00 @ 1321.74
CANCEL SELL 1000.00 @ 1321.97
PASSIVE SELL 380.00 @ 1321.84
AGGRESSIVE BUY 820.00 @ 1321.74
PASSIVE BUY 1020.00 @ 1321.63
PASSIVE BUY 1580.00 @ 1321.54
PASSIVE BUY 740.00 @ 1321.59
PASSIVE BUY 1700.00 @ 1321.66
PASSIVE BUY 1220.00 @ 1321.60
PASSIVE SELL 2020.00 @ 1321.73
CANCEL SELL 1900.00 @ 1321.88
AGGRESSIVE BUY 780.00 @ 1321.73
AGGRESSIVE SELL 2180.00 @ 1321.63
PASSIVE BUY 1620.00 @ 1321.68
AGGRESSIVE BUY 2500.00 @ 1321.76
AGGRESSIVE BUY 1860.00 @ 1321.83
AGGRESSIVE SELL 740.00 @ 1321.76
PASSIVE SELL 1900.00 @ 1321.80
AGGRESSIVE SELL 1860.00 @ 1321.68
PASSIVE SELL 2060.00 @ 1321.75
PASSIVE SELL 620.00 @ 1321.78
PASSIVE BUY 1380.00 @ 1321.62
PASSIVE BUY 1620.00 @ 1321.69
CANCEL BUY 540.00 @ 1321.63
CANCEL BUY 1580.00 @ 1321.54
CANCEL BUY 740.00 @ 1321.59
CANCEL BUY 1220.00 @ 1321.60
CANCEL BUY 20.00 @ 1321.68
CANCEL BUY 1380.00 @ 1321.62
CANCEL BUY 1620.00 @ 1321.69
PASSIVE BUY 2100.00 @ 1321.64
PASSIVE BUY 2340.00 @ 1321.66
PASSIVE BUY 1140.00 @ 1321.72
PASSIVE BUY 2380.00 @ 1321.71
AGGRESSIVE BUY 1460.00 @ 1321.75
AGGRESSIVE BUY 1820.00 @ 1321.80
AGGRESSIVE BUY 1540.00 @ 1321.83
PASSIVE SELL 1140.00 @ 1321.89
PASSIVE SELL 1060.00 @ 1321.85
PASSIVE BUY 1220.00 @ 1321.72
AGGRESSIVE SELL 1580.00 @ 1321.72
PASSIVE BUY 2500.00 @ 1321.73
PASSIVE SELL 1340.00 @ 1321.85
AGGRESSIVE SELL 2300.00 @ 1321.73
PASSIVE SELL 1300.00 @ 1321.87
PASSIVE SELL 2060.00 @ 1321.81
CANCEL SELL 1140.00 @ 1321.89
PASSIVE SELL 620.00 @ 1321.84
PASSIVE SELL 2060.00 @ 1321.75
CANCEL SELL 1300.00 @ 1321.87
AGGRESSIVE BUY 1860.00 @ 1321.75
PASSIVE SELL 1620.00 @ 1321.88
CANCEL SELL 1620.00 @ 1321.88
PASSIVE SELL 700.00 @ 1321.81
PASSIVE BUY 2020.00 @ 1321.73
PASSIVE SELL 1500.00 @ 1321.81
PASSIVE SELL 1420.00 @ 1321.87
CANCEL SELL 1420.00 @ 1321.87
PASSIVE BUY 2180.00 @ 1321.62
PASSIVE BUY 1700.00 @ 1321.73
PASSIVE BUY 1060.00 @ 1321.71
PASSIVE SELL 1660.00 @ 1321.83
PASSIVE SELL 620.00 @ 1321.86
AGGRESSIVE SELL 660.00 @ 1321.73
PASSIVE SELL 1340.00 @ 1321.74
CANCEL SELL -1220.00 @ 1321.86
CANCEL SELL 620.00 @ 1321.86
AGGRESSIVE BUY 2900.00 @ 1321.76
CANCEL BUY 2100.00 @ 1321.64
CANCEL BUY 2340.00 @ 1321.66
CANCEL BUY -2380.00 @ 1321.71
CANCEL BUY 780.00 @ 1321.72
CANCEL BUY -1560.00 @ 1321.73
CANCEL BUY 2180.00 @ 1321.62
CANCEL BUY 1700.00 @ 1321.73
CANCEL BUY 1060.00 @ 1321.71
CANCEL BUY 1360.00 @ 1321.76
PASSIVE SELL 1220.00 @ 1321.87
PASSIVE SELL 1020.00 @ 1321.66
AGGRESSIVE BUY 1020.00 @ 1321.66
PASSIVE BUY 2420.00 @ 1321.79
PASSIVE SELL 2180.00 @ 1321.87
PASSIVE BUY 1540.00 @ 1321.75
PASSIVE BUY 2820.00 @ 1321.69
AGGRESSIVE SELL 1980.00 @ 1321.79
AGGRESSIVE SELL 540.00 @ 1321.75
PASSIVE BUY 1860.00 @ 1321.71
PASSIVE SELL 1180.00 @ 1321.84
PASSIVE SELL 1100.00 @ 1321.82
AGGRESSIVE SELL 460.00 @ 1321.75
AGGRESSIVE SELL 1780.00 @ 1321.71
PASSIVE SELL 740.00 @ 1321.74
CANCEL SELL -1220.00 @ 1321.87
CANCEL SELL 2180.00 @ 1321.87
PASSIVE BUY 1620.00 @ 1321.70
PASSIVE BUY 2780.00 @ 1321.73
AGGRESSIVE BUY 1540.00 @ 1321.81
PASSIVE SELL 1060.00 @ 1321.81
PASSIVE SELL 2020.00 @ 1321.86
PASSIVE BUY 1300.00 @ 1321.74
AGGRESSIVE BUY 2260.00 @ 1321.81
PASSIVE BUY 2900.00 @ 1321.80
PASSIVE SELL 1220.00 @ 1321.83
AGGRESSIVE BUY 1580.00 @ 1321.81
PASSIVE BUY 1500.00 @ 1321.78
