data/output/QUEEN.txt
PASSIVE BUY 2380.00 @ 509.73
PASSIVE SELL 1540.00 @ 510.29
PASSIVE SELL 900.00 @ 510.13
PASSIVE SELL 860.00 @ 510.01
PASSIVE SELL 2260.00 @ 509.91
PASSIVE SELL 1660.00 @ 509.77
PASSIVE SELL 420.00 @ 509.74
AGGRESSIVE SELL 900.00 @ 509.73
PASSIVE BUY 780.00 @ 509.61
AGGRESSIVE BUY 2100.00 @ 509.83
AGGRESSIVE SELL 2180.00 @ 509.74
AGGRESSIVE BUY 1460.00 @ 509.74
AGGRESSIVE SELL 1780.00 @ 509.73
PASSIVE BUY 2060.00 @ 509.50
PASSIVE SELL 2180.00 @ 509.83
CANCEL SELL 1540.00 @ 510.29
PASSIVE BUY 900.00 @ 509.52
AGGRESSIVE BUY 1060.00 @ 509.77
PASSIVE BUY 2180.00 @ 509.79
PASSIVE SELL 1300.00 @ 509.82
PASSIVE BUY 1980.00 @ 509.79
PASSIVE SELL 940.00 @ 509.90
PASSIVE SELL 660.00 @ 509.82
PASSIVE SELL 700.00 @ 509.86
CANCEL SELL 900.00 @ 510.13
AGGRESSIVE SELL 820.00 @ 509.79
AGGRESSIVE SELL 1860.00 @ 509.79
AGGRESSIVE BUY 1260.00 @ 509.82
AGGRESSIVE BUY 1580.00 @ 509.83
PASSIVE SELL 1260.00 @ 509.85
PASSIVE BUY 2100.00 @ 509.80
PASSIVE SELL 500.00 @ 509.81
CANCEL SELL 860.00 @ 510.01
AGGRESSIVE SELL 2220.00 @ 509.79
AGGRESSIVE BUY 2740.00 @ 509.85
PASSIVE BUY 1860.00 @ 509.70
PASSIVE BUY 1620.00 @ 509.84
CANCEL BUY 780.00 @ 509.61
CANCEL BUY 2060.00 @ 509.50
CANCEL BUY 900.00 @ 509.52
CANCEL BUY 60.00 @ 509.77
CANCEL BUY 1360.00 @ 509.79
CANCEL BUY 1860.00 @ 509.70
CANCEL BUY 1620.00 @ 509.84
PASSIVE SELL 580.00 @ 509.79
PASSIVE SELL 1180.00 @ 509.82
PASSIVE SELL 1380.00 @ 509.82
AGGRESSIVE BUY 1580.00 @ 509.82
PASSIVE SELL 1340.00 @ 509.85
AGGRESSIVE BUY 2580.00 @ 509.85
PASSIVE BUY 2500.00 @ 509.67
PASSIVE SELL 700.00 @ 509.89
PASSIVE SELL 1700.00 @ 509.89
PASSIVE BUY 1980.00 @ 509.71
PASSIVE SELL 1700.00 @ 509.96
AGGRESSIVE SELL 1500.00 @ 509.71
PASSIVE SELL 1860.00 @ 509.77
CANCEL SELL 1700.00 @ 509.96
PASSIVE SELL 1940.00 @ 509.75
CANCEL SELL 2260.00 @ 509.91
PASSIVE BUY 2620.00 @ 509.68
PASSIVE BUY 2380.00 @ 509.67
PASSIVE SELL 660.00 @ 509.75
AGGRESSIVE SELL 1460.00 @ 509.69
CANCEL SELL 940.00 @ 509.90
PASSIVE SELL 1300.00 @ 509.73
CANCEL SELL -700.00 @ 509.89
CANCEL SELL 1700.00 @ 509.89
PASSIVE BUY 1860.00 @ 509.61
PASSIVE BUY 1700.00 @ 509.65
AGGRESSIVE BUY 2100.00 @ 509.73
PASSIVE SELL 2020.00 @ 509.79
AGGRESSIVE BUY 2900.00 @ 509.77
AGGRESSIVE BUY 1060.00 @ 509.77
PASSIVE SELL 700.00 @ 509.72
AGGRESSIVE BUY 1580.00 @ 509.79
PASSIVE BUY 2900.00 @ 509.71
PASSIVE BUY 1420.00 @ 509.61
PASSIVE SELL 1020.00 @ 509.84
PASSIVE SELL 1260.00 @ 509.88
AGGRESSIVE SELL 1420.00 @ 509.71
PASSIVE BUY 1620.00 @ 509.72
AGGRESSIVE SELL 1900.00 @ 509.71
PASSIVE BUY 1060.00 @ 509.70
PASSIVE BUY 1060.00 @ 509.69
CANCEL BUY -2500.00 @ 509.67
CANCEL BUY 2620.00 @ 509.68
CANCEL BUY 2380.00 @ 509.67
CANCEL BUY -1860.00 @ 509.61
CANCEL BUY 1700.00 @ 509.65
CANCEL BUY 1200.00 @ 509.71
CANCEL BUY 1420.00 @ 509.61
CANCEL BUY 1060.00 @ 509.70
CANCEL BUY 1060.00 @ 509.69
PASSIVE BUY 1500.00 @ 509.74
PASSIVE BUY 2140.00 @ 509.62
PASSIVE SELL 2140.00 @ 509.84
PASSIVE SELL 1220.00 @ 509.84
PASSIVE SELL 940.00 @ 509.89
PASSIVE SELL 2260.00 @ 509.89
AGGRESSIVE BUY 2700.00 @ 509.84
PASSIVE SELL 1500.00 @ 509.82
PASSIVE SELL 1260.00 @ 509.93
CANCEL SELL 1260.00 @ 509.93
PASSIVE SELL 1860.00 @ 509.86
AGGRESSIVE BUY 1340.00 @ 509.82
AGGRESSIVE SELL 940.00 @ 509.74
AGGRESSIVE BUY 2220.00 @ 509.84
PASSIVE BUY 1940.00 @ 509.63
PASSIVE BUY 940.00 @ 509.76
PASSIVE BUY 2300.00 @ 509.80
AGGRESSIVE SELL 460.00 @ 509.80
PASSIVE BUY 2620.00 @ 509.70
PASSIVE SELL 1300.00 @ 509.82
PASSIVE BUY 1780.00 @ 509.67
CANCEL BUY 560.00 @ 509.74
CANCEL BUY 2140.00 @ 509.62
CANCEL BUY 1940.00 @ 509.63
CANCEL BUY 940.00 @ 509.76
CANCEL BUY 1840.00 @ 509.80
CANCEL BUY 2620.00 @ 509.70
CANCEL BUY 1780.00 @ 509.67
PASSIVE SELL 620.00 @ 509.85
PASSIVE BUY 940.00 @ 509.78
AGGRESSIVE SELL 1060.00 @ 509.71
CANCEL SELL -940.00 @ 509.89
CANCEL SELL 2260.00 @ 509.89
PASSIVE BUY 2260.00 @ 509.63
AGGRESSIVE BUY 1860.00 @ 509.79
PASSIVE SELL 860.00 @ 509.84
PASSIVE SELL 1140.00 @ 509.90
AGGRESSIVE BUY 2500.00 @ 509.84
AGGRESSIVE BUY 2940.00 @ 509.86
PASSIVE BUY 940.00 @ 509.79
PASSIVE SELL 1900.00 @ 509.89
AGGRESSIVE BUY 1900.00 @ 509.86
PASSIVE BUY 1700.00 @ 509.82
AGGRESSIVE BUY 1900.00 @ 509.89
PASSIVE BUY 1220.00 @ 509.87
AGGRESSIVE BUY 780.00 @ 509.89
AGGRESSIVE SELL 1220.00 @ 509.87
PASSIVE SELL 1540.00 @ 509.84
AGGRESSIVE BUY 1420.00 @ 509.84
PASSIVE SELL 1140.00 @ 509.83
PASSIVE SELL 700.00 @ 509.89
AGGRESSIVE BUY 2340.00 @ 509.89
PASSIVE BUY 1540.00 @ 509.76
AGGRESSIVE BUY 1540.00 @ 509.93
PASSIVE BUY 1500.00 @ 509.94
PASSIVE BUY 2860.00 @ 510.08
CANCEL BUY 2260.00 @ 509.63
CANCEL BUY -1740.00 @ 509.79
CANCEL BUY 940.00 @ 509.79
CANCEL BUY 1700.00 @ 509.82
CANCEL BUY 1540.00 @ 509.76
CANCEL BUY 220.00 @ 509.93
CANCEL BUY 1500.00 @ 509.94
CANCEL BUY 2860.00 @ 510.08
PASSIVE BUY 2420.00 @ 509.77
PASSIVE BUY 1700.00 @ 509.72
PASSIVE SELL 1660.00 @ 510.06
PASSIVE BUY 2860.00 @ 509.81
PASSIVE SELL 420.00 @ 510.18
PASSIVE BUY 940.00 @ 509.78
PASSIVE SELL 2260.00 @ 510.15
PASSIVE BUY 2660.00 @ 509.82
PASSIVE SELL 2140.00 @ 510.09
PASSIVE SELL 1740.00 @ 510.10
PASSIVE BUY 2780.00 @ 509.78
PASSIVE BUY 1580.00 @ 509.98
AGGRESSIVE BUY 2460.00 @ 510.09
PASSIVE BUY 2580.00 @ 509.87
CANCEL BUY 2420.00 @ 509.77
CANCEL BUY 1700.00 @ 509.72
CANCEL BUY 2860.00 @ 509.81
CANCEL BUY -940.00 @ 509.78
CANCEL BUY 2660.00 @ 509.82
CANCEL BUY 2780.00 @ 509.78
CANCEL BUY 1580.00 @ 509.98
CANCEL BUY 2580.00 @ 509.87
PASSIVE SELL 1620.00 @ 509.98
PASSIVE SELL 780.00 @ 509.92
AGGRESSIVE BUY 2420.00 @ 510.09
PASSIVE BUY 1260.00 @ 510.05
AGGRESSIVE BUY 740.00 @ 510.09
PASSIVE SELL 420.00 @ 510.14
AGGRESSIVE SELL 820.00 @ 510.05
PASSIVE SELL 1100.00 @ 510.20
AGGRESSIVE SELL 460.00 @ 509.99
CANCEL SELL 1100.00 @ 510.20
AGGRESSIVE BUY 1260.00 @ 510.06
AGGRESSIVE BUY 1820.00 @ 510.10
PASSIVE SELL 380.00 @ 510.22
PASSIVE BUY 980.00 @ 510.05
AGGRESSIVE BUY 2540.00 @ 510.15
AGGRESSIVE SELL 2100.00 @ 510.05
AGGRESSIVE SELL 1180.00 @ 510.04
PASSIVE SELL 1980.00 @ 509.97
PASSIVE SELL 2060.00 @ 509.94
AGGRESSIVE BUY 1540.00 @ 509.94
PASSIVE SELL 2020.00 @ 509.93
CANCEL SELL 380.00 @ 510.22
AGGRESSIVE BUY 2660.00 @ 509.97
AGGRESSIVE BUY 2100.00 @ 510.04
AGGRESSIVE BUY 1740.00 @ 510.13
AGGRESSIVE SELL 2140.00 @ 510.13
PASSIVE SELL 1180.00 @ 510.07
PASSIVE BUY 2220.00 @ 509.98
PASSIVE BUY 740.00 @ 510.00
PASSIVE SELL 1340.00 @ 510.04
AGGRESSIVE BUY 1780.00 @ 510.07
PASSIVE SELL 820.00 @ 510.01
PASSIVE SELL 420.00 @ 510.02
AGGRESSIVE BUY 1460.00 @ 510.07
AGGRESSIVE BUY 740.00 @ 510.09
AGGRESSIVE SELL 1580.00 @ 510.07
AGGRESSIVE BUY 2020.00 @ 510.13
PASSIVE BUY 2340.00 @ 510.10
AGGRESSIVE SELL 1780.00 @ 510.10
PASSIVE BUY 900.00 @ 510.12
PASSIVE BUY 2300.00 @ 509.98
PASSIVE SELL 820.00 @ 510.22
AGGRESSIVE BUY 2340.00 @ 510.21
PASSIVE BUY 900.00 @ 510.19
AGGRESSIVE BUY 2940.00 @ 510.27
CANCEL BUY -2220.00 @ 509.98
CANCEL BUY 740.00 @ 510.00
CANCEL BUY 560.00 @ 510.10
CANCEL BUY 900.00 @ 510.12
CANCEL BUY 2300.00 @ 509.98
CANCEL BUY 720.00 @ 510.21
CANCEL BUY 900.00 @ 510.19
CANCEL BUY 2120.00 @ 510.27
PASSIVE SELL 1940.00 @ 510.30
AGGRESSIVE BUY 1380.00 @ 510.30
AGGRESSIVE BUY 1100.00 @ 510.34
PASSIVE BUY 1340.00 @ 510.49
AGGRESSIVE SELL 460.00 @ 510.49
PASSIVE BUY 1060.00 @ 510.60
PASSIVE BUY 740.00 @ 510.58
PASSIVE BUY 1180.00 @ 510.68
AGGRESSIVE SELL 1740.00 @ 510.60
PASSIVE BUY 1620.00 @ 510.56
PASSIVE BUY 1460.00 @ 510.50
AGGRESSIVE SELL 460.00 @ 510.60
PASSIVE BUY 2260.00 @ 510.48
CANCEL BUY 540.00 @ 510.34
CANCEL BUY 880.00 @ 510.49
CANCEL BUY 40.00 @ 510.60
CANCEL BUY 740.00 @ 510.58
CANCEL BUY 1620.00 @ 510.56
CANCEL BUY 1460.00 @ 510.50
CANCEL BUY 2260.00 @ 510.48
PASSIVE SELL 1020.00 @ 510.33
PASSIVE SELL 1060.00 @ 510.15
AGGRESSIVE BUY 1620.00 @ 510.33
PASSIVE SELL 1300.00 @ 510.31
AGGRESSIVE BUY 1780.00 @ 510.41
PASSIVE SELL 540.00 @ 510.58
PASSIVE SELL 2180.00 @ 510.49
PASSIVE SELL 1580.00 @ 510.47
AGGRESSIVE BUY 1060.00 @ 510.47
PASSIVE SELL 1580.00 @ 510.54
AGGRESSIVE BUY 2620.00 @ 510.49
PASSIVE SELL 2140.00 @ 510.46
PASSIVE SELL 2140.00 @ 510.42
PASSIVE BUY 1140.00 @ 510.34
AGGRESSIVE SELL 1500.00 @ 510.41
PASSIVE BUY 2100.00 @ 510.28
PASSIVE BUY 820.00 @ 510.35
